Workbook

Sheet maestro 
A1: Codigo | B1: Codigo_Producto_Sistema | C1: Codigo_Tipo_Producto | D1: Codigo_Familia | E1: Codigo_Tipo_Entrada | F1: Codigo_Tipo_Salida | G1: Codigo_Categoria_Producto | H1: Codigo_SubZona_Almacen | I1: Nombre | J1: Descripcion | K1: Codigo_Barra | L1: Codigo_Barra_Secundario | M1: Codigo_UM_Vol | N1: Volumen_Neto | O1: Volumen_Bruto | P1: Codigo_UM_Peso | Q1: Peso_Neto | R1: Peso_Bruto | S1: Codigo_UM_Dimension | T1: Altura | U1: Ancho | V1: Profundidad | W1: Codigo_UM_Presentacion_Defecto | X1: Codigo_Pallet_Por_Defecto | Y1: Codigo_UM_Palletizado | Z1: Codigo_UM_Peso_Pallets | AA1: Peso_Pallet | AB1: Codigo_UM_Dimension_Pallets | AC1: Altura_Pallet | AD1: Ancho_Pallet | AE1: Profundidad_Pallet | AF1: Codigo_Secundario | AG1: Stock_Minimo_Reposicion | AH1: Stock_Minimo_Reubicacion | AI1: Codigo_UM_Moneda | AJ1: Valor_Comercial | AK1: Valor_Asegurado | AL1: Valor_Costo | AM1: Tasa_Cambio | AN1: Coef_Unidad_Almacenamiento | AO1: Codigo_Cliente | AP1: Codigo_Cliente | AQ1: nombre_Cliente | AR1: Codigo_Empresa | AS1: Codigo_Empresa_Sector | AT1: CDXU_Num1 | AU1: CDXU_Num2 | AV1: CDXU_Num3 | AW1: CDXU_Num4 | AX1: CDXU_Alf_Corto1 | AY1: CDXU_Alf_Corto2 | AZ1: CDXU_Alf_Corto3 | BA1: CDXU_Alf_Corto4 | BB1: CDXU_Alf_Largo1 | BC1: CDXU_Alf_Largo2 | BD1: CDXU_Alf_Largo3 | BE1: CDXU_Alf_Largo4 | BF1: CDXU_Fecha1 | BG1: CDXU_Fecha2 | BH1: CDXU_Fecha3 | BI1: CDXU_Fecha4 | BJ1: CDXU_Bit1 | BK1: CDXU_Bit2 | BL1: CDXU_Bit3 | BM1: CDXU_Bit4 | BN1: Codigo_Talle_Cab | BO1: Codigo_Color_Cab | BP1: Codigo_Sabor_Cab | BQ1: Codigo_Fragancia_Cab | BR1: Codigo_Atrib1_Cab | BS1: Codigo_Atrib2_Cab | BT1: Sistema Destino | BU1: Acción (Agregar "A" , Modificar "M", Baja "B") | BV1: CompaniaDestino | BW1: Id_subzona
A2: AS12HUPI | C2: Normal | D2: ELECTRO | F2: FIFO | G2: GRAL | H2: Sub Zona B DER | I2: Trend 12 C - Unidad Int, Frio/Calor | J2: Trend 12 C - Unidad Int, Frio/Calor | K2: 7798083661333 | L2: 7798083661333 | M2: mt3 | N2: 0.069471 | O2: 0.069471 | P2: kg | Q2: 10 | R2: 10 | S2: mts | T2: 0.31 | U2: 0.83 | V2: 0.27 | W2: UNIDAD | AO2: 0240 | AP2: 240 | AQ2: aires acondicionados | BT2: OXDEP | BU2: A | BV2: ENCOPRESS_OXDEP | BW2: 3
A3: AS12HUPO | C3: Normal | D3: ELECTRO | F3: FIFO | G3: GRAL | H3: Sub Zona B DER | I3: Trend 12 C - Unidad ext, Frio/Calor | J3: Trend 12 C - Unidad ext, Frio/Calor | K3: 7798083661340 | L3: 7798083661340 | M3: mt3 | N3: 0.16371912 | O3: 0.16371912 | P3: kg | Q3: 30 | R3: 30 | S3: mts | T3: 0.53 | U3: 0.844 | V3: 0.366 | W3: UNIDAD | AO3: 0240 | AP3: 240 | AQ3: aires acondicionados | BT3: OXDEP | BU3: A | BV3: ENCOPRESS_OXDEP | BW3: 3
A4: AS12HVGI | C4: Normal | D4: ELECTRO | F4: FIFO | G4: GRAL | H4: Sub Zona B DER | I4: Green 12 unidad int, Fr?o / Calor | J4: Green 12 unidad int, Fr?o / Calor | K4: 7798083661173 | L4: 7798083661173 | M4: mt3 | N4: 0.098553 | O4: 0.098553 | P4: kg | Q4: 13 | R4: 13 | S4: mts | T4: 0.38 | U4: 0.91 | V4: 0.285 | W4: UNIDAD | AO4: 0240 | AP4: 240 | AQ4: aires acondicionados | BT4: OXDEP | BU4: A | BV4: ENCOPRESS_OXDEP | BW4: 3
A5: AS18HUPO | C5: Normal | D5: ELECTRO | F5: FIFO | G5: GRAL | H5: Sub Zona B DER | I5: TREND 18C-UNIDAD EXT, FRIO/CALOR | J5: TREND 18C-UNIDAD EXT, FRIO/CALOR | K5: 7798083661364 | L5: 7798083661364 | M5: mt3 | N5: 0.18067 | O5: 0.18067 | P5: kg | Q5: 45 | R5: 45 | S5: mts | T5: 0.58 | U5: 0.89 | V5: 0.35 | W5: UNIDAD | AO5: 0240 | AP5: 240 | AQ5: aires acondicionados | BT5: OXDEP | BU5: A | BV5: ENCOPRESS_OXDEP | BW5: 3
A6: AS22HUPI | C6: Normal | D6: ELECTRO | F6: FIFO | G6: GRAL | H6: Sub Zona B DER | I6: Trend 22 C - Unidad int, Frio/Calor | J6: Trend 22 C - Unidad int, Frio/Calor | K6: 7798083661371 | L6: 7798083661371 | M6: mt3 | N6: 0.14012 | O6: 0.14012 | P6: kg | Q6: 19 | R6: 19 | S6: mts | T6: 0.4 | U6: 1.13 | V6: 0.31 | W6: UNIDAD | AO6: 0240 | AP6: 240 | AQ6: aires acondicionados | BT6: OXDEP | BU6: A | BV6: ENCOPRESS_OXDEP | BW6: 3
A7: AS22HVGO | C7: Normal | D7: ELECTRO | F7: FIFO | G7: GRAL | H7: Sub Zona B DER | I7: Green 22 c-unidad ext, frio/calor | J7: Green 22 c-unidad ext, frio/calor | K7: 7798083661210 | L7: 7798083661210 | M7: mt3 | N7: 0.316932 | O7: 0.316932 | P7: kg | Q7: 63 | R7: 63 | S7: mts | T7: 0.77 | U7: 0.98 | V7: 0.42 | W7: UNIDAD | AO7: 0240 | AP7: 240 | AQ7: aires acondicionados | BT7: OXDEP | BU7: A | BV7: ENCOPRESS_OXDEP | BW7: 3
A8: gwh18mcc3i | C8: Normal | D8: ELECTRO | F8: FIFO | G8: GRAL | H8: Sub Zona B DER | I8: Bee 18 - Unidad int, Fr?o/Calor | J8: Bee 18 - Unidad int, Fr?o/Calor | K8: 7798083661517 | L8: 7798083661517 | M8: mt3 | N8: 0.1285488 | O8: 0.1285488 | P8: kg | Q8: 17 | R8: 17 | S8: mts | T8: 0.395 | U8: 1.13 | V8: 0.288 | W8: UNIDAD | AO8: 0240 | AP8: 240 | AQ8: aires acondicionados | BT8: OXDEP | BU8: A | BV8: ENCOPRESS_OXDEP | BW8: 3
A9: gwh18mcc3o | C9: Normal | D9: ELECTRO | F9: FIFO | G9: GRAL | H9: Sub Zona B DER | I9: Bee 18 c- Unidad ext, Fr?o/Calor | J9: Bee 18 c- Unidad ext, Fr?o/Calor | K9: 7798083661524 | L9: 7798083661524 | M9: mt3 | N9: 0.308654 | O9: 0.308654 | P9: kg | Q9: 50 | R9: 50 | S9: mts | T9: 0.74 | U9: 0.97 | V9: 0.43 | W9: UNIDAD | AO9: 0240 | AP9: 240 | AQ9: aires acondicionados | BT9: OXDEP | BU9: A | BV9: ENCOPRESS_OXDEP | BW9: 3
A10: TLF10X1 | C10: Normal | D10: ALIMENTO | F10: FIFO | G10: GRAL | H10: Sub Zona F DER | I10: Topador L.Fino x 1 Kg. | J10: Topador L.Fino x 1 Kg. | K10: 7792004000145 | L10: 7792004000145 | M10: mt3 | N10: 0.0014976 | O10: 0.0014976 | P10: kg | Q10: 1 | R10: 1 | S10: mts | T10: 0.12 | U10: 0.24 | V10: 0.052 | W10: UNIDAD | AO10: 0244 | AP10: 244 | AQ10: Molino arrocero | BT10: OXDEP | BU10: A | BV10: ENCOPRESS_OXDEP | BW10: 7
A11: TCLF10X1 | C11: Normal | D11: ALIMENTO | F11: FIFO | G11: GRAL | H11: Sub Zona F DER | I11: Tio Carlos L.Fino 10 x 1 Kg. | J11: Tio Carlos L.Fino 10 x 1 Kg. | K11: 7792006000124 | L11: 7792006000124 | M11: mt3 | N11: 0.0013104 | O11: 0.0013104 | P11: kg | Q11: 1 | R11: 1 | S11: mts | T11: 0.12 | U11: 0.21 | V11: 0.052 | W11: UNIDAD | AO11: 0244 | AP11: 244 | AQ11: Molino arrocero | BT11: OXDEP | BU11: A | BV11: ENCOPRESS_OXDEP | BW11: 7
A12: TCLF10X1 | C12: Normal | D12: ALIMENTO | F12: FIFO | G12: GRAL | H12: Sub Zona F DER | I12: Tio Carlos L.Fino 10 x 1 Kg. | J12: Tio Carlos L.Fino 10 x 1 Kg. | K12: 7792006000124 | L12: 7792006000124 | M12: mt3 | N12: 0.0013104 | O12: 0.0013104 | P12: kg | Q12: 1 | R12: 1 | S12: mts | T12: 0.12 | U12: 0.21 | V12: 0.052 | W12: UNIDAD | AO12: 0244 | AP12: 244 | AQ12: Molino arrocero | BT12: OXDEP | BU12: A | BV12: ENCOPRESS_OXDEP | BW12: 7
A13: TCLF10X1 | C13: Normal | D13: ALIMENTO | F13: FIFO | G13: GRAL | H13: Sub Zona F DER | I13: Tio Carlos L.Fino 10 x 1 Kg. | J13: Tio Carlos L.Fino 10 x 1 Kg. | K13: 7792006000124 | L13: 7792006000124 | M13: mt3 | N13: 0.0013104 | O13: 0.0013104 | P13: kg | Q13: 1 | R13: 1 | S13: mts | T13: 0.12 | U13: 0.21 | V13: 0.052 | W13: UNIDAD | AO13: 0244 | AP13: 244 | AQ13: Molino arrocero | BT13: OXDEP | BU13: A | BV13: ENCOPRESS_OXDEP | BW13: 7
... A29: AS18HVGO | C29: Normal | D29: ELECTRO | F29: FIFO | G29: GRAL | H29: Sub Zona B DER | I29: Green 18 C - Unidad Ext. Frio/Calor | J29: Green 18 C - Unidad Ext. Frio/Calor | K29: 7798083661203 | L29: 7798083661203 | M29: mt3 | N29: 0.26656 | O29: 0.26656 | P29: kg | Q29: 55 | R29: 55 | S29: mts | T29: 0.68 | U29: 0.98 | V29: 0.4 | W29: UNIDAD | AO29: 0240 | AP29: 240 | AQ29: aires acondicionados | BT29: OXDEP | BU29: A | BV29: ENCOPRESS_OXDEP | BW29: 3
A30: GWC18MCA2I | C30: Normal | D30: ELECTRO | F30: FIFO | G30: GRAL | H30: Sub Zona B DER | I30: ALPHA 18 F - Unidad Int. Frio | J30: ALPHA 18 F - Unidad Int. Frio | K30: GWC18MCA2I | L30: GWC18MCA2I | M30: mt3 | N30: 0.12198 | O30: 0.12198 | P30: kg | Q30: 16 | R30: 16 | S30: mts | T30: 0.38 | U30: 1.07 | V30: 0.3 | W30: UNIDAD | AO30: 0240 | AP30: 240 | AQ30: aires acondicionados | BT30: OXDEP | BU30: A | BV30: ENCOPRESS_OXDEP | BW30: 3
A31: GWC18MCA2O | C31: Normal | D31: ELECTRO | F31: FIFO | G31: GRAL | H31: Sub Zona B DER | I31: ALPHA 18 F - Unidad Ext. Frio | J31: ALPHA 18 F - Unidad Ext. Frio | K31: GWC18MCA2O | L31: GWC18MCA2O | M31: mt3 | N31: 0.308654 | O31: 0.308654 | P31: kg | Q31: 50 | R31: 50 | S31: mts | T31: 0.74 | U31: 0.97 | V31: 0.43 | W31: UNIDAD | AO31: 0240 | AP31: 240 | AQ31: aires acondicionados | BT31: OXDEP | BU31: A | BV31: ENCOPRESS_OXDEP | BW31: 3
A32: GWC24MDD2I | C32: Normal | D32: ELECTRO | F32: FIFO | G32: GRAL | H32: Sub Zona B DER | I32: Delta 24 F - Unidad Int. Frio | J32: Delta 24 F - Unidad Int. Frio | K32: GWC24MDD2I | L32: GWC24MDD2I | M32: mt3 | N32: 0.14013978 | O32: 0.14013978 | P32: kg | Q32: 20.5 | R32: 20.5 | S32: mts | T32: 0.33 | U32: 1.067 | V32: 0.398 | W32: UNIDAD | AO32: 0240 | AP32: 240 | AQ32: aires acondicionados | BT32: OXDEP | BU32: A | BV32: ENCOPRESS_OXDEP | BW32: 3
A33: GWC24MDD2O | C33: Normal | D33: ELECTRO | F33: FIFO | G33: GRAL | H33: Sub Zona B DER | I33: Delta 24 F - Unidad Ext. Frio | J33: Delta 24 F - Unidad Ext. Frio | K33: GWC24MDD2O | L33: GWC24MDD2O | M33: mt3 | N33: 0.3534615 | O33: 0.3534615 | P33: kg | Q33: 56 | R33: 56 | S33: mts | T33: 0.75 | U33: 1.029 | V33: 0.458 | W33: UNIDAD | AO33: 0240 | AP33: 240 | AQ33: aires acondicionados | BT33: OXDEP | BU33: A | BV33: ENCOPRESS_OXDEP | BW33: 3
A34: GWH24MDC3I | C34: Normal | D34: ELECTRO | F34: FIFO | G34: GRAL | H34: Sub Zona B DER | I34: Bee 24 - Unidad Int. Frio/Calor | J34: Bee 24 - Unidad Int. Frio/Calor | K34: 7791354000268 | L34: 7791354000268 | M34: mt3 | N34: 0.14046534 | O34: 0.14046534 | P34: kg | Q34: 20.5 | R34: 20.5 | S34: mts | T34: 0.328 | U34: 1.076 | V34: 0.398 | W34: UNIDAD | AO34: 0240 | AP34: 240 | AQ34: aires acondicionados | BT34: OXDEP | BU34: A | BV34: ENCOPRESS_OXDEP | BW34: 3
A35: GWH24MDC3O | C35: Normal | D35: ELECTRO | F35: FIFO | G35: GRAL | H35: Sub Zona B DER | I35: Bee 24 - Unidad Ext. Frio/Calor | J35: Bee 24 - Unidad Ext. Frio/Calor | K35: 7791354000264 | L35: 7791354000264 | M35: mt3 | N35: 0.443115 | O35: 0.443115 | P35: kg | Q35: 61 | R35: 61 | S35: mts | T35: 0.75 | U35: 1.29 | V35: 0.458 | W35: UNIDAD | AO35: 0240 | AP35: 240 | AQ35: aires acondicionados | BT35: OXDEP | BU35: A | BV35: ENCOPRESS_OXDEP | BW35: 3

Sheet Analisis
A2: Métrica | B2: Fórmula utilizada | C2: resultado | E2: interpretacion
A3: Total registros | B3: =FILAS('maestro '!b1:BW35)' | C3: =ROWS('maestro '!B2:BW35) -> 34 | E3: tamaño del DataSet
A4: Total columnas | B4: =COLUMNAS('maestro '!A1:BW36)' | C4: =COLUMNS('maestro '!B1:BX36) -> 75 | E4: Cantidad de Atributos
A5: Celdas totales | B5: Registros * Columnas' | C5: =C4*C3 -> 2550 | E5: Cantidad Celdas analizadas
A6: Celdas vacías | B6: =CONTAR.BLANCO(maestro '!A2:BW35)' | C6: =COUNTBLANK('maestro '!A2:BW35) -> 1598 | E6: Sin Informacion
A7: Celdas con informacion | B7: Celdas totales - Celdas vacias | C7: =C5-C6 -> 952 | E7: Con informacion
A8: % Indice Cobertura de Datos | B8: Celdas con informacion /Celdas totales ' | C8: =C7/C5 -> 0.37333333 | E8: Porcentaje de informacion presente
A10: Relevancia de los Atributos
A12: Campo | B12: categoria | C12: Relevancia operativa | E12: Descripcion
A13: Codigo | B13: Identificación del Material | C13: Critico | E13: Estos campos permiten identificar de forma única el artículo.
A14: Codigo_Producto_Sistema | B14: Identificación del Material | C14: Critico | E14: Estos campos permiten identificar de forma única el artículo.
A15: Codigo_Tipo_Producto | B15: Clasificación del Material | C15: Critico | E15: Permiten agrupar y analizar productos.
A16: Codigo_Familia | B16: Clasificación del Material | C16: Critico | E16: Permiten agrupar y analizar productos.
A17: Codigo_Tipo_Entrada | B17: Operación e Interfaces | C17: Media | E17: Campos usados para integración entre sistemas.
A18: Codigo_Tipo_Salida | B18: Operación e Interfaces | C18: Media | E18: Campos usados para integración entre sistemas.
A19: Codigo_Categoria_Producto | B19: Clasificación del Material | C19: Critico | E19: Permiten agrupar y analizar productos.
A20: Codigo_SubZona_Almacen | B20: Inventario y Reposición | C20: Alta | E20: Ayudan a gestionar stock.
A21: Nombre | B21: Identificación del Material | C21: Critico | E21: Estos campos permiten identificar de forma única el artículo.
A22: Descripcion | B22: Identificación del Material | C22: Critico | E22: Estos campos permiten identificar de forma única el artículo.
A23: Codigo_Barra | B23: Identificación del Material | C23: Critico | E23: Estos campos permiten identificar de forma única el artículo.
... A87: Id_subzona | B87: Inventario y Reposición | C87: Alta | E87: Ayudan a gestionar stock.
A89: Tabla 1 - Resumen Ejecutivo
A91: Relevancia operativa | B91: Recuento de Relevancia operativa
A92: Alta | B92: 31
A93: Baja | B93: 20
A94: Critico | B94: 16
A95: Media | B95: 8
A96: Total general | B96: 75
A106: Se identificaron 47 atributos (16 críticos y 31 de alta relevancia) que tienen impacto directo sobre la operación logística y serán considerados para el análisis de calidad de datos.
A108: Tabla 2 - Atributos a Analizar
A111: Campo | B111: categoria | C111: Relevancia operativa
A112: Codigo | B112: Identificación del Material | C112: Critico
A113: Codigo_Producto_Sistema | B113: Identificación del Material | C113: Critico
A114: Codigo_Tipo_Producto | B114: Clasificación del Material | C114: Critico
A115: Codigo_Familia | B115: Clasificación del Material | C115: Critico
A116: Codigo_Categoria_Producto | B116: Clasificación del Material | C116: Critico
A117: Nombre | B117: Identificación del Material | C117: Critico
A118: Descripcion | B118: Identificación del Material | C118: Critico
A119: Codigo_Barra | B119: Identificación del Material | C119: Critico
A120: Codigo_Barra_Secundario | B120: Identificación del Material | C120: Critico
...
